{
 "cells": [
  {
   "cell_type": "code",
   "execution_count": null,
   "id": "50021596-cd72-430e-9cde-4bac64b99a9d",
   "metadata": {},
   "outputs": [],
   "source": [
    "# config\n",
    "import os\n",
    "\n",
    "# specify the shape of input for our network\n",
    "image_shape = (28, 28, 1)\n",
    "\n",
    "# specify the batch size and number of epochs\n",
    "batch_size = 64\n",
    "epochs = 100\n",
    "\n",
    "# define path to base output directory\n",
    "base_output = 'output'\n",
    "\n",
    "# use base output path to derive the path to serialized model along with training history plot\n",
    "model_path = os.path.sep.join([base_output, 'siamese_model'])\n",
    "plot_path = os.path.sep.join([base_output, 'plot.png'])"
   ]
  },
  {
   "cell_type": "code",
   "execution_count": null,
   "id": "d66dc362-4be7-4b1b-8a5a-a4c682c7a873",
   "metadata": {},
   "outputs": [],
   "source": [
    "# Predictions\n",
    "# imports\n",
    "#from tensorflow.keras.models import load_model\n",
    "from tensorflow import keras\n",
    "from imutils.paths import list_images\n",
    "import matplotlib.pyplot as plt\n",
    "import cv2 as cv\n",
    "import numpy as np\n",
    "import argparse\n",
    "\n",
    "# input to network\n",
    "test_input = 'examples'\n",
    "\n",
    "# grab the test dataset image paths and randomly generate a total of 10 image pairs\n",
    "print('[INFO] loading test dataset...')\n",
    "test_image_paths = list(list_images(test_input))\n",
    "np.random.seed(42)\n",
    "pairs = np.random.choice(test_image_paths, size=(10, 2))\n",
    "\n",
    "# load model from disk\n",
    "print('[INFO] loading siamese model...')\n",
    "#model = load_model('output\\siamese_model\\saved_model')\n",
    "model = keras.models.load_model('siamese_model')\n",
    "\n",
    "# loop over all image pairs\n",
    "for (i, (path_A, path_B)) in enumerate(pairs):\n",
    "    # load both images and convert them to grayscale\n",
    "    image_A = cv.imread(path_A, 0)\n",
    "    image_B = cv.imread(path_B, 0)\n",
    "    \n",
    "    # create a copy of both images for visualization\n",
    "    orig_A = image_A.copy()\n",
    "    orig_B = image_B.copy()\n",
    "    \n",
    "    # add channel dimension to both images\n",
    "    image_A = np.expand_dims(image_A, axis=-1)\n",
    "    image_B = np.expand_dims(image_B, axis=-1)\n",
    "    \n",
    "    # add batch dimension to both images\n",
    "    image_A = np.expand_dims(image_A, axis=0)\n",
    "    image_B = np.expand_dims(image_B, axis=0)\n",
    "    \n",
    "    # scale pixel values to a range of [0, 1]\n",
    "    image_A = image_A/255.0\n",
    "    image_B = image_B/255.0\n",
    "    \n",
    "    # use our siamese model to make predictions on image pair, indicating whether or not\n",
    "    # images belong to same class\n",
    "    preds = model.predict([image_A, image_B])\n",
    "    proba = preds[0][0]\n",
    "    \n",
    "    # initialize the figure \n",
    "    fig = plt.figure(f'Pair: {i+1}', figsize=(4, 2))\n",
    "    plt.subtitle(f'Similarity: {proba:.2f}')\n",
    "    \n",
    "    # show first image\n",
    "    ax = fig.add_subplot(1, 2, 1)\n",
    "    plt.imshow(orig_A, cmap=plt.cm.gray)\n",
    "    plt.axis('off')\n",
    "    \n",
    "    # show first image\n",
    "    ax = fig.add_subplot(1, 2, 2)\n",
    "    plt.imshow(orig_B, cmap=plt.cm.gray)\n",
    "    plt.axis('off')\n",
    "    \n",
    "    plt.show"
   ]
  },
  {
   "cell_type": "code",
   "execution_count": null,
   "id": "5f9dd4bd-de0a-4349-9602-5897eda3690f",
   "metadata": {},
   "outputs": [
    {
     "name": "stderr",
     "output_type": "stream",
     "text": [
      "ERROR:root:Internal Python error in the inspect module.\n",
      "Below is the traceback from this internal error.\n",
      "\n",
      "ERROR:root:Internal Python error in the inspect module.\n",
      "Below is the traceback from this internal error.\n",
      "\n",
      "ERROR:root:Internal Python error in the inspect module.\n",
      "Below is the traceback from this internal error.\n",
      "\n"
     ]
    },
    {
     "name": "stdout",
     "output_type": "stream",
     "text": [
      "Traceback (most recent call last):\n",
      "  File \"C:\\Users\\b84145862\\Miniconda\\envs\\tensorflow\\lib\\site-packages\\IPython\\core\\interactiveshell.py\", line 3441, in run_code\n",
      "    exec(code_obj, self.user_global_ns, self.user_ns)\n",
      "  File \"C:\\Users\\B84145~1\\AppData\\Local\\Temp/ipykernel_6076/3196110305.py\", line 2, in <module>\n",
      "    model = keras.models.load_model('sm')\n",
      "  File \"C:\\Users\\b84145862\\Miniconda\\envs\\tensorflow\\lib\\site-packages\\tensorflow_core\\python\\keras\\saving\\save.py\", line 150, in load_model\n",
      "    return saved_model_load.load(filepath, compile)\n",
      "  File \"C:\\Users\\b84145862\\Miniconda\\envs\\tensorflow\\lib\\site-packages\\tensorflow_core\\python\\keras\\saving\\saved_model\\load.py\", line 89, in load\n",
      "    model = tf_load.load_internal(path, loader_cls=KerasObjectLoader)\n",
      "  File \"C:\\Users\\b84145862\\Miniconda\\envs\\tensorflow\\lib\\site-packages\\tensorflow_core\\python\\saved_model\\load.py\", line 552, in load_internal\n",
      "    export_dir)\n",
      "  File \"C:\\Users\\b84145862\\Miniconda\\envs\\tensorflow\\lib\\site-packages\\tensorflow_core\\python\\keras\\saving\\saved_model\\load.py\", line 119, in __init__\n",
      "    self._finalize()\n",
      "  File \"C:\\Users\\b84145862\\Miniconda\\envs\\tensorflow\\lib\\site-packages\\tensorflow_core\\python\\keras\\saving\\saved_model\\load.py\", line 157, in _finalize\n",
      "    created_layers={layer.name: layer for layer in node.layers})\n",
      "  File \"C:\\Users\\b84145862\\Miniconda\\envs\\tensorflow\\lib\\site-packages\\tensorflow_core\\python\\keras\\engine\\network.py\", line 1903, in reconstruct_from_config\n",
      "    process_node(layer, node_data)\n",
      "  File \"C:\\Users\\b84145862\\Miniconda\\envs\\tensorflow\\lib\\site-packages\\tensorflow_core\\python\\keras\\engine\\network.py\", line 1851, in process_node\n",
      "    output_tensors = layer(input_tensors, **kwargs)\n",
      "  File \"C:\\Users\\b84145862\\Miniconda\\envs\\tensorflow\\lib\\site-packages\\tensorflow_core\\python\\keras\\engine\\base_layer.py\", line 773, in __call__\n",
      "    outputs = call_fn(cast_inputs, *args, **kwargs)\n",
      "  File \"C:\\Users\\b84145862\\Miniconda\\envs\\tensorflow\\lib\\site-packages\\tensorflow_core\\python\\keras\\engine\\network.py\", line 712, in call\n",
      "    raise NotImplementedError('When subclassing the `Model` class, you should'\n",
      "NotImplementedError: When subclassing the `Model` class, you should implement a `call` method.\n",
      "\n",
      "During handling of the above exception, another exception occurred:\n",
      "\n",
      "Traceback (most recent call last):\n",
      "  File \"C:\\Users\\b84145862\\Miniconda\\envs\\tensorflow\\lib\\site-packages\\IPython\\core\\interactiveshell.py\", line 2061, in showtraceback\n",
      "    stb = value._render_traceback_()\n",
      "AttributeError: 'NotImplementedError' object has no attribute '_render_traceback_'\n",
      "\n",
      "During handling of the above exception, another exception occurred:\n",
      "\n",
      "Traceback (most recent call last):\n",
      "  File \"C:\\Users\\b84145862\\Miniconda\\envs\\tensorflow\\lib\\site-packages\\IPython\\core\\ultratb.py\", line 1101, in get_records\n",
      "    return _fixed_getinnerframes(etb, number_of_lines_of_context, tb_offset)\n",
      "  File \"C:\\Users\\b84145862\\Miniconda\\envs\\tensorflow\\lib\\site-packages\\IPython\\core\\ultratb.py\", line 248, in wrapped\n",
      "    return f(*args, **kwargs)\n",
      "  File \"C:\\Users\\b84145862\\Miniconda\\envs\\tensorflow\\lib\\site-packages\\IPython\\core\\ultratb.py\", line 281, in _fixed_getinnerframes\n",
      "    records = fix_frame_records_filenames(inspect.getinnerframes(etb, context))\n",
      "  File \"C:\\Users\\b84145862\\Miniconda\\envs\\tensorflow\\lib\\inspect.py\", line 1502, in getinnerframes\n",
      "    frameinfo = (tb.tb_frame,) + getframeinfo(tb, context)\n",
      "  File \"C:\\Users\\b84145862\\Miniconda\\envs\\tensorflow\\lib\\inspect.py\", line 1460, in getframeinfo\n",
      "    filename = getsourcefile(frame) or getfile(frame)\n",
      "  File \"C:\\Users\\b84145862\\Miniconda\\envs\\tensorflow\\lib\\inspect.py\", line 696, in getsourcefile\n",
      "    if getattr(getmodule(object, filename), '__loader__', None) is not None:\n",
      "  File \"C:\\Users\\b84145862\\Miniconda\\envs\\tensorflow\\lib\\inspect.py\", line 733, in getmodule\n",
      "    if ismodule(module) and hasattr(module, '__file__'):\n",
      "  File \"C:\\Users\\b84145862\\Miniconda\\envs\\tensorflow\\lib\\site-packages\\tensorflow\\__init__.py\", line 50, in __getattr__\n",
      "    module = self._load()\n",
      "  File \"C:\\Users\\b84145862\\Miniconda\\envs\\tensorflow\\lib\\site-packages\\tensorflow\\__init__.py\", line 44, in _load\n",
      "    module = _importlib.import_module(self.__name__)\n",
      "  File \"C:\\Users\\b84145862\\Miniconda\\envs\\tensorflow\\lib\\importlib\\__init__.py\", line 127, in import_module\n",
      "    return _bootstrap._gcd_import(name[level:], package, level)\n",
      "  File \"<frozen importlib._bootstrap>\", line 1006, in _gcd_import\n",
      "  File \"<frozen importlib._bootstrap>\", line 983, in _find_and_load\n",
      "  File \"<frozen importlib._bootstrap>\", line 965, in _find_and_load_unlocked\n",
      "ModuleNotFoundError: No module named 'tensorflow_core.estimator'\n",
      "Traceback (most recent call last):\n",
      "  File \"C:\\Users\\b84145862\\Miniconda\\envs\\tensorflow\\lib\\site-packages\\IPython\\core\\interactiveshell.py\", line 3441, in run_code\n",
      "    exec(code_obj, self.user_global_ns, self.user_ns)\n",
      "  File \"C:\\Users\\B84145~1\\AppData\\Local\\Temp/ipykernel_6076/3196110305.py\", line 2, in <module>\n",
      "    model = keras.models.load_model('sm')\n",
      "  File \"C:\\Users\\b84145862\\Miniconda\\envs\\tensorflow\\lib\\site-packages\\tensorflow_core\\python\\keras\\saving\\save.py\", line 150, in load_model\n",
      "    return saved_model_load.load(filepath, compile)\n",
      "  File \"C:\\Users\\b84145862\\Miniconda\\envs\\tensorflow\\lib\\site-packages\\tensorflow_core\\python\\keras\\saving\\saved_model\\load.py\", line 89, in load\n",
      "    model = tf_load.load_internal(path, loader_cls=KerasObjectLoader)\n",
      "  File \"C:\\Users\\b84145862\\Miniconda\\envs\\tensorflow\\lib\\site-packages\\tensorflow_core\\python\\saved_model\\load.py\", line 552, in load_internal\n",
      "    export_dir)\n",
      "  File \"C:\\Users\\b84145862\\Miniconda\\envs\\tensorflow\\lib\\site-packages\\tensorflow_core\\python\\keras\\saving\\saved_model\\load.py\", line 119, in __init__\n",
      "    self._finalize()\n",
      "  File \"C:\\Users\\b84145862\\Miniconda\\envs\\tensorflow\\lib\\site-packages\\tensorflow_core\\python\\keras\\saving\\saved_model\\load.py\", line 157, in _finalize\n",
      "    created_layers={layer.name: layer for layer in node.layers})\n",
      "  File \"C:\\Users\\b84145862\\Miniconda\\envs\\tensorflow\\lib\\site-packages\\tensorflow_core\\python\\keras\\engine\\network.py\", line 1903, in reconstruct_from_config\n",
      "    process_node(layer, node_data)\n",
      "  File \"C:\\Users\\b84145862\\Miniconda\\envs\\tensorflow\\lib\\site-packages\\tensorflow_core\\python\\keras\\engine\\network.py\", line 1851, in process_node\n",
      "    output_tensors = layer(input_tensors, **kwargs)\n",
      "  File \"C:\\Users\\b84145862\\Miniconda\\envs\\tensorflow\\lib\\site-packages\\tensorflow_core\\python\\keras\\engine\\base_layer.py\", line 773, in __call__\n",
      "    outputs = call_fn(cast_inputs, *args, **kwargs)\n",
      "  File \"C:\\Users\\b84145862\\Miniconda\\envs\\tensorflow\\lib\\site-packages\\tensorflow_core\\python\\keras\\engine\\network.py\", line 712, in call\n",
      "    raise NotImplementedError('When subclassing the `Model` class, you should'\n",
      "NotImplementedError: When subclassing the `Model` class, you should implement a `call` method.\n",
      "\n",
      "During handling of the above exception, another exception occurred:\n",
      "\n",
      "Traceback (most recent call last):\n",
      "  File \"C:\\Users\\b84145862\\Miniconda\\envs\\tensorflow\\lib\\site-packages\\IPython\\core\\interactiveshell.py\", line 2061, in showtraceback\n",
      "    stb = value._render_traceback_()\n",
      "AttributeError: 'NotImplementedError' object has no attribute '_render_traceback_'\n",
      "\n",
      "During handling of the above exception, another exception occurred:\n",
      "\n",
      "Traceback (most recent call last):\n",
      "  File \"C:\\Users\\b84145862\\Miniconda\\envs\\tensorflow\\lib\\site-packages\\IPython\\core\\interactiveshell.py\", line 3361, in run_ast_nodes\n",
      "    if (await self.run_code(code, result,  async_=asy)):\n",
      "  File \"C:\\Users\\b84145862\\Miniconda\\envs\\tensorflow\\lib\\site-packages\\IPython\\core\\interactiveshell.py\", line 3458, in run_code\n",
      "    self.showtraceback(running_compiled_code=True)\n",
      "  File \"C:\\Users\\b84145862\\Miniconda\\envs\\tensorflow\\lib\\site-packages\\IPython\\core\\interactiveshell.py\", line 2064, in showtraceback\n",
      "    value, tb, tb_offset=tb_offset)\n",
      "  File \"C:\\Users\\b84145862\\Miniconda\\envs\\tensorflow\\lib\\site-packages\\IPython\\core\\ultratb.py\", line 1368, in structured_traceback\n",
      "    self, etype, value, tb, tb_offset, number_of_lines_of_context)\n",
      "  File \"C:\\Users\\b84145862\\Miniconda\\envs\\tensorflow\\lib\\site-packages\\IPython\\core\\ultratb.py\", line 1268, in structured_traceback\n",
      "    self, etype, value, tb, tb_offset, number_of_lines_of_context\n",
      "  File \"C:\\Users\\b84145862\\Miniconda\\envs\\tensorflow\\lib\\site-packages\\IPython\\core\\ultratb.py\", line 1125, in structured_traceback\n",
      "    tb_offset)\n",
      "  File \"C:\\Users\\b84145862\\Miniconda\\envs\\tensorflow\\lib\\site-packages\\IPython\\core\\ultratb.py\", line 1082, in format_exception_as_a_whole\n",
      "    last_unique, recursion_repeat = find_recursion(orig_etype, evalue, records)\n",
      "  File \"C:\\Users\\b84145862\\Miniconda\\envs\\tensorflow\\lib\\site-packages\\IPython\\core\\ultratb.py\", line 382, in find_recursion\n",
      "    return len(records), 0\n",
      "TypeError: object of type 'NoneType' has no len()\n",
      "\n",
      "During handling of the above exception, another exception occurred:\n",
      "\n",
      "Traceback (most recent call last):\n",
      "  File \"C:\\Users\\b84145862\\Miniconda\\envs\\tensorflow\\lib\\site-packages\\IPython\\core\\interactiveshell.py\", line 2061, in showtraceback\n",
      "    stb = value._render_traceback_()\n",
      "AttributeError: 'TypeError' object has no attribute '_render_traceback_'\n",
      "\n",
      "During handling of the above exception, another exception occurred:\n",
      "\n",
      "Traceback (most recent call last):\n",
      "  File \"C:\\Users\\b84145862\\Miniconda\\envs\\tensorflow\\lib\\site-packages\\IPython\\core\\ultratb.py\", line 1101, in get_records\n",
      "    return _fixed_getinnerframes(etb, number_of_lines_of_context, tb_offset)\n",
      "  File \"C:\\Users\\b84145862\\Miniconda\\envs\\tensorflow\\lib\\site-packages\\IPython\\core\\ultratb.py\", line 248, in wrapped\n",
      "    return f(*args, **kwargs)\n",
      "  File \"C:\\Users\\b84145862\\Miniconda\\envs\\tensorflow\\lib\\site-packages\\IPython\\core\\ultratb.py\", line 281, in _fixed_getinnerframes\n",
      "    records = fix_frame_records_filenames(inspect.getinnerframes(etb, context))\n",
      "  File \"C:\\Users\\b84145862\\Miniconda\\envs\\tensorflow\\lib\\inspect.py\", line 1502, in getinnerframes\n",
      "    frameinfo = (tb.tb_frame,) + getframeinfo(tb, context)\n",
      "  File \"C:\\Users\\b84145862\\Miniconda\\envs\\tensorflow\\lib\\inspect.py\", line 1460, in getframeinfo\n",
      "    filename = getsourcefile(frame) or getfile(frame)\n",
      "  File \"C:\\Users\\b84145862\\Miniconda\\envs\\tensorflow\\lib\\inspect.py\", line 696, in getsourcefile\n",
      "    if getattr(getmodule(object, filename), '__loader__', None) is not None:\n",
      "  File \"C:\\Users\\b84145862\\Miniconda\\envs\\tensorflow\\lib\\inspect.py\", line 733, in getmodule\n",
      "    if ismodule(module) and hasattr(module, '__file__'):\n",
      "  File \"C:\\Users\\b84145862\\Miniconda\\envs\\tensorflow\\lib\\site-packages\\tensorflow\\__init__.py\", line 50, in __getattr__\n",
      "    module = self._load()\n",
      "  File \"C:\\Users\\b84145862\\Miniconda\\envs\\tensorflow\\lib\\site-packages\\tensorflow\\__init__.py\", line 44, in _load\n",
      "    module = _importlib.import_module(self.__name__)\n",
      "  File \"C:\\Users\\b84145862\\Miniconda\\envs\\tensorflow\\lib\\importlib\\__init__.py\", line 127, in import_module\n",
      "    return _bootstrap._gcd_import(name[level:], package, level)\n",
      "  File \"<frozen importlib._bootstrap>\", line 1006, in _gcd_import\n",
      "  File \"<frozen importlib._bootstrap>\", line 983, in _find_and_load\n",
      "  File \"<frozen importlib._bootstrap>\", line 965, in _find_and_load_unlocked\n",
      "ModuleNotFoundError: No module named 'tensorflow_core.estimator'\n",
      "Traceback (most recent call last):\n",
      "  File \"C:\\Users\\b84145862\\Miniconda\\envs\\tensorflow\\lib\\site-packages\\IPython\\core\\interactiveshell.py\", line 3441, in run_code\n",
      "    exec(code_obj, self.user_global_ns, self.user_ns)\n",
      "  File \"C:\\Users\\B84145~1\\AppData\\Local\\Temp/ipykernel_6076/3196110305.py\", line 2, in <module>\n",
      "    model = keras.models.load_model('sm')\n",
      "  File \"C:\\Users\\b84145862\\Miniconda\\envs\\tensorflow\\lib\\site-packages\\tensorflow_core\\python\\keras\\saving\\save.py\", line 150, in load_model\n",
      "    return saved_model_load.load(filepath, compile)\n",
      "  File \"C:\\Users\\b84145862\\Miniconda\\envs\\tensorflow\\lib\\site-packages\\tensorflow_core\\python\\keras\\saving\\saved_model\\load.py\", line 89, in load\n",
      "    model = tf_load.load_internal(path, loader_cls=KerasObjectLoader)\n",
      "  File \"C:\\Users\\b84145862\\Miniconda\\envs\\tensorflow\\lib\\site-packages\\tensorflow_core\\python\\saved_model\\load.py\", line 552, in load_internal\n",
      "    export_dir)\n",
      "  File \"C:\\Users\\b84145862\\Miniconda\\envs\\tensorflow\\lib\\site-packages\\tensorflow_core\\python\\keras\\saving\\saved_model\\load.py\", line 119, in __init__\n",
      "    self._finalize()\n",
      "  File \"C:\\Users\\b84145862\\Miniconda\\envs\\tensorflow\\lib\\site-packages\\tensorflow_core\\python\\keras\\saving\\saved_model\\load.py\", line 157, in _finalize\n",
      "    created_layers={layer.name: layer for layer in node.layers})\n",
      "  File \"C:\\Users\\b84145862\\Miniconda\\envs\\tensorflow\\lib\\site-packages\\tensorflow_core\\python\\keras\\engine\\network.py\", line 1903, in reconstruct_from_config\n",
      "    process_node(layer, node_data)\n",
      "  File \"C:\\Users\\b84145862\\Miniconda\\envs\\tensorflow\\lib\\site-packages\\tensorflow_core\\python\\keras\\engine\\network.py\", line 1851, in process_node\n",
      "    output_tensors = layer(input_tensors, **kwargs)\n",
      "  File \"C:\\Users\\b84145862\\Miniconda\\envs\\tensorflow\\lib\\site-packages\\tensorflow_core\\python\\keras\\engine\\base_layer.py\", line 773, in __call__\n",
      "    outputs = call_fn(cast_inputs, *args, **kwargs)\n",
      "  File \"C:\\Users\\b84145862\\Miniconda\\envs\\tensorflow\\lib\\site-packages\\tensorflow_core\\python\\keras\\engine\\network.py\", line 712, in call\n",
      "    raise NotImplementedError('When subclassing the `Model` class, you should'\n",
      "NotImplementedError: When subclassing the `Model` class, you should implement a `call` method.\n",
      "\n",
      "During handling of the above exception, another exception occurred:\n",
      "\n",
      "Traceback (most recent call last):\n",
      "  File \"C:\\Users\\b84145862\\Miniconda\\envs\\tensorflow\\lib\\site-packages\\IPython\\core\\interactiveshell.py\", line 2061, in showtraceback\n",
      "    stb = value._render_traceback_()\n",
      "AttributeError: 'NotImplementedError' object has no attribute '_render_traceback_'\n",
      "\n",
      "During handling of the above exception, another exception occurred:\n",
      "\n",
      "Traceback (most recent call last):\n",
      "  File \"C:\\Users\\b84145862\\Miniconda\\envs\\tensorflow\\lib\\site-packages\\IPython\\core\\interactiveshell.py\", line 3361, in run_ast_nodes\n",
      "    if (await self.run_code(code, result,  async_=asy)):\n",
      "  File \"C:\\Users\\b84145862\\Miniconda\\envs\\tensorflow\\lib\\site-packages\\IPython\\core\\interactiveshell.py\", line 3458, in run_code\n",
      "    self.showtraceback(running_compiled_code=True)\n",
      "  File \"C:\\Users\\b84145862\\Miniconda\\envs\\tensorflow\\lib\\site-packages\\IPython\\core\\interactiveshell.py\", line 2064, in showtraceback\n",
      "    value, tb, tb_offset=tb_offset)\n",
      "  File \"C:\\Users\\b84145862\\Miniconda\\envs\\tensorflow\\lib\\site-packages\\IPython\\core\\ultratb.py\", line 1368, in structured_traceback\n",
      "    self, etype, value, tb, tb_offset, number_of_lines_of_context)\n",
      "  File \"C:\\Users\\b84145862\\Miniconda\\envs\\tensorflow\\lib\\site-packages\\IPython\\core\\ultratb.py\", line 1268, in structured_traceback\n",
      "    self, etype, value, tb, tb_offset, number_of_lines_of_context\n",
      "  File \"C:\\Users\\b84145862\\Miniconda\\envs\\tensorflow\\lib\\site-packages\\IPython\\core\\ultratb.py\", line 1125, in structured_traceback\n",
      "    tb_offset)\n",
      "  File \"C:\\Users\\b84145862\\Miniconda\\envs\\tensorflow\\lib\\site-packages\\IPython\\core\\ultratb.py\", line 1082, in format_exception_as_a_whole\n",
      "    last_unique, recursion_repeat = find_recursion(orig_etype, evalue, records)\n",
      "  File \"C:\\Users\\b84145862\\Miniconda\\envs\\tensorflow\\lib\\site-packages\\IPython\\core\\ultratb.py\", line 382, in find_recursion\n",
      "    return len(records), 0\n",
      "TypeError: object of type 'NoneType' has no len()\n",
      "\n",
      "During handling of the above exception, another exception occurred:\n",
      "\n",
      "Traceback (most recent call last):\n",
      "  File \"C:\\Users\\b84145862\\Miniconda\\envs\\tensorflow\\lib\\site-packages\\IPython\\core\\interactiveshell.py\", line 2061, in showtraceback\n",
      "    stb = value._render_traceback_()\n",
      "AttributeError: 'TypeError' object has no attribute '_render_traceback_'\n",
      "\n",
      "During handling of the above exception, another exception occurred:\n",
      "\n",
      "Traceback (most recent call last):\n",
      "  File \"C:\\Users\\b84145862\\Miniconda\\envs\\tensorflow\\lib\\site-packages\\IPython\\core\\interactiveshell.py\", line 2944, in _run_cell\n",
      "    return runner(coro)\n",
      "  File \"C:\\Users\\b84145862\\Miniconda\\envs\\tensorflow\\lib\\site-packages\\IPython\\core\\async_helpers.py\", line 68, in _pseudo_sync_runner\n",
      "    coro.send(None)\n",
      "  File \"C:\\Users\\b84145862\\Miniconda\\envs\\tensorflow\\lib\\site-packages\\IPython\\core\\interactiveshell.py\", line 3170, in run_cell_async\n",
      "    interactivity=interactivity, compiler=compiler, result=result)\n",
      "  File \"C:\\Users\\b84145862\\Miniconda\\envs\\tensorflow\\lib\\site-packages\\IPython\\core\\interactiveshell.py\", line 3380, in run_ast_nodes\n",
      "    self.showtraceback()\n",
      "  File \"C:\\Users\\b84145862\\Miniconda\\envs\\tensorflow\\lib\\site-packages\\IPython\\core\\interactiveshell.py\", line 2064, in showtraceback\n",
      "    value, tb, tb_offset=tb_offset)\n",
      "  File \"C:\\Users\\b84145862\\Miniconda\\envs\\tensorflow\\lib\\site-packages\\IPython\\core\\ultratb.py\", line 1368, in structured_traceback\n",
      "    self, etype, value, tb, tb_offset, number_of_lines_of_context)\n",
      "  File \"C:\\Users\\b84145862\\Miniconda\\envs\\tensorflow\\lib\\site-packages\\IPython\\core\\ultratb.py\", line 1268, in structured_traceback\n",
      "    self, etype, value, tb, tb_offset, number_of_lines_of_context\n",
      "  File \"C:\\Users\\b84145862\\Miniconda\\envs\\tensorflow\\lib\\site-packages\\IPython\\core\\ultratb.py\", line 1143, in structured_traceback\n",
      "    chained_exceptions_tb_offset)\n",
      "  File \"C:\\Users\\b84145862\\Miniconda\\envs\\tensorflow\\lib\\site-packages\\IPython\\core\\ultratb.py\", line 1082, in format_exception_as_a_whole\n",
      "    last_unique, recursion_repeat = find_recursion(orig_etype, evalue, records)\n",
      "  File \"C:\\Users\\b84145862\\Miniconda\\envs\\tensorflow\\lib\\site-packages\\IPython\\core\\ultratb.py\", line 382, in find_recursion\n",
      "    return len(records), 0\n",
      "TypeError: object of type 'NoneType' has no len()\n",
      "\n",
      "During handling of the above exception, another exception occurred:\n",
      "\n",
      "Traceback (most recent call last):\n",
      "  File \"C:\\Users\\b84145862\\Miniconda\\envs\\tensorflow\\lib\\site-packages\\IPython\\core\\interactiveshell.py\", line 2061, in showtraceback\n",
      "    stb = value._render_traceback_()\n",
      "AttributeError: 'TypeError' object has no attribute '_render_traceback_'\n",
      "\n",
      "During handling of the above exception, another exception occurred:\n",
      "\n",
      "Traceback (most recent call last):\n",
      "  File \"C:\\Users\\b84145862\\Miniconda\\envs\\tensorflow\\lib\\site-packages\\IPython\\core\\ultratb.py\", line 1101, in get_records\n",
      "    return _fixed_getinnerframes(etb, number_of_lines_of_context, tb_offset)\n",
      "  File \"C:\\Users\\b84145862\\Miniconda\\envs\\tensorflow\\lib\\site-packages\\IPython\\core\\ultratb.py\", line 248, in wrapped\n",
      "    return f(*args, **kwargs)\n",
      "  File \"C:\\Users\\b84145862\\Miniconda\\envs\\tensorflow\\lib\\site-packages\\IPython\\core\\ultratb.py\", line 281, in _fixed_getinnerframes\n",
      "    records = fix_frame_records_filenames(inspect.getinnerframes(etb, context))\n",
      "  File \"C:\\Users\\b84145862\\Miniconda\\envs\\tensorflow\\lib\\inspect.py\", line 1502, in getinnerframes\n",
      "    frameinfo = (tb.tb_frame,) + getframeinfo(tb, context)\n",
      "  File \"C:\\Users\\b84145862\\Miniconda\\envs\\tensorflow\\lib\\inspect.py\", line 1460, in getframeinfo\n",
      "    filename = getsourcefile(frame) or getfile(frame)\n",
      "  File \"C:\\Users\\b84145862\\Miniconda\\envs\\tensorflow\\lib\\inspect.py\", line 696, in getsourcefile\n",
      "    if getattr(getmodule(object, filename), '__loader__', None) is not None:\n",
      "  File \"C:\\Users\\b84145862\\Miniconda\\envs\\tensorflow\\lib\\inspect.py\", line 733, in getmodule\n",
      "    if ismodule(module) and hasattr(module, '__file__'):\n",
      "  File \"C:\\Users\\b84145862\\Miniconda\\envs\\tensorflow\\lib\\site-packages\\tensorflow\\__init__.py\", line 50, in __getattr__\n",
      "    module = self._load()\n",
      "  File \"C:\\Users\\b84145862\\Miniconda\\envs\\tensorflow\\lib\\site-packages\\tensorflow\\__init__.py\", line 44, in _load\n",
      "    module = _importlib.import_module(self.__name__)\n",
      "  File \"C:\\Users\\b84145862\\Miniconda\\envs\\tensorflow\\lib\\importlib\\__init__.py\", line 127, in import_module\n",
      "    return _bootstrap._gcd_import(name[level:], package, level)\n",
      "  File \"<frozen importlib._bootstrap>\", line 1006, in _gcd_import\n",
      "  File \"<frozen importlib._bootstrap>\", line 983, in _find_and_load\n",
      "  File \"<frozen importlib._bootstrap>\", line 965, in _find_and_load_unlocked\n",
      "ModuleNotFoundError: No module named 'tensorflow_core.estimator'\n"
     ]
    }
   ],
   "source": [
    "from tensorflow import keras\n",
    "model = keras.models.load_model('sm')"
   ]
  },
  {
   "cell_type": "code",
   "execution_count": null,
   "id": "476c953d-550c-4874-991c-e468afd55c6f",
   "metadata": {},
   "outputs": [],
   "source": []
  }
 ],
 "metadata": {
  "kernelspec": {
   "display_name": "Python 3 (ipykernel)",
   "language": "python",
   "name": "python3"
  },
  "language_info": {
   "codemirror_mode": {
    "name": "ipython",
    "version": 3
   },
   "file_extension": ".py",
   "mimetype": "text/x-python",
   "name": "python",
   "nbconvert_exporter": "python",
   "pygments_lexer": "ipython3",
   "version": "3.7.10"
  }
 },
 "nbformat": 4,
 "nbformat_minor": 5
}
